{"name": "test_fail3", "status": "failed", "statusDetails": {"message": "AssertionError: assert False", "trace": "def test_fail3():\n>       assert False\nE       assert False\n\ntests\\test_fail.py:16: AssertionError"}, "start": 1667947181646, "stop": 1667947181646, "uuid": "d980dee0-f624-4f9e-bbdb-ce3b0e4474fa", "historyId": "8a3b48d1deba5b8335830a3565466832", "testCaseId": "85f1ba8a367b705ef4badba28254ff65", "fullName": "tests.test_fail#test_fail3", "labels": [{"name": "parentSuite", "value": "tests"}, {"name": "suite", "value": "test_fail"}, {"name": "host", "value": "note_nN1ce"}, {"name": "thread", "value": "7736-MainThread"}, {"name": "framework", "value": "pytest"}, {"name": "language", "value": "cpython3"}, {"name": "package", "value": "tests.test_fail"}]}