{"name": "test_fail1", "status": "failed", "statusDetails": {"message": "AssertionError: assert False", "trace": "def test_fail1():\n>       assert False\nE       assert False\n\ntests\\test_fail.py:8: AssertionError"}, "start": 1667947181634, "stop": 1667947181634, "uuid": "da47d88e-d2e4-4b7a-9b63-2c50b78a0c79", "historyId": "43cd5556548abd3e4036828ebf87f693", "testCaseId": "a7325c86b11237c538c480ac1b9dd8d6", "fullName": "tests.test_fail#test_fail1", "labels": [{"name": "parentSuite", "value": "tests"}, {"name": "suite", "value": "test_fail"}, {"name": "host", "value": "note_nN1ce"}, {"name": "thread", "value": "7736-MainThread"}, {"name": "framework", "value": "pytest"}, {"name": "language", "value": "cpython3"}, {"name": "package", "value": "tests.test_fail"}]}