{"name": "test_fail", "status": "failed", "statusDetails": {"message": "AssertionError: assert False", "trace": "def test_fail():\n>       assert False\nE       assert False\n\ntests\\test_fail.py:4: AssertionError"}, "start": 1667947181598, "stop": 1667947181598, "uuid": "cee3c10e-f59e-491d-93e8-a6da7168f9f9", "historyId": "1c6d798198e5fb12f50877ff5d2f655b", "testCaseId": "cd2384dd64342692c894db79d0a45ba3", "fullName": "tests.test_fail#test_fail", "labels": [{"name": "parentSuite", "value": "tests"}, {"name": "suite", "value": "test_fail"}, {"name": "host", "value": "note_nN1ce"}, {"name": "thread", "value": "7736-MainThread"}, {"name": "framework", "value": "pytest"}, {"name": "language", "value": "cpython3"}, {"name": "package", "value": "tests.test_fail"}]}