{"name": "test_fail2", "status": "failed", "statusDetails": {"message": "AssertionError: assert False", "trace": "def test_fail2():\n>       assert False\nE       assert False\n\ntests\\test_fail.py:12: AssertionError"}, "start": 1667947181645, "stop": 1667947181646, "uuid": "c70d9fcc-53a5-4c1c-b92c-20d888e90500", "historyId": "b58b7e867ac7b16c913dc6636c3475a0", "testCaseId": "43dedf1ef931d11918e6b05b9130314b", "fullName": "tests.test_fail#test_fail2", "labels": [{"name": "parentSuite", "value": "tests"}, {"name": "suite", "value": "test_fail"}, {"name": "host", "value": "note_nN1ce"}, {"name": "thread", "value": "7736-MainThread"}, {"name": "framework", "value": "pytest"}, {"name": "language", "value": "cpython3"}, {"name": "package", "value": "tests.test_fail"}]}